Workbook

Sheet Welcome
B1: WT spreadsheet by gszabi99 | G1: v2.0
A4: Guided weaponry data spreadsheet: link
A5: Unused assets of War Thunder: link
A6: Feedback: link
A7: Discord: link

Sheet Updates
A1: Updates
A2: Version | B2: Name | C2: Release | E2: Announcement (UTC) | F2: Internal date in game files | G2: First devblog | I2: Last update release to first devblog | J2: First devblog to release | K2: Last dev server to release | L2: Time between updates | M2: Date diff | V2: Avg announcement time | X2: Avg release | Y2: Avg first devblog
A3: 1.27 | B3: - | C3: 41304 | D3: =CHOOSE(WEEKDAY(C3,2),"Monday","Tuesday","Wednesday","Thursday","Friday","Saturday","Sunday") -> Wednesday | E3: - | F3: - | G3: - | H3: - | I3: - | J3: - | K3: - | L3: - | X3: =C3 -> 41304
A4: 1.29 | B4: - | C4: 41352 | D4: =CHOOSE(WEEKDAY(C4,2),"Monday","Tuesday","Wednesday","Thursday","Friday","Saturday","Sunday") -> Tuesday | E4: - | F4: - | G4: - | H4: - | I4: - | J4: - | K4: - | L4: =C4-C3 -> 48 | X4: =C4 -> 41352
A5: 1.31 | B5: - | C5: 41436 | D5: =CHOOSE(WEEKDAY(C5,2),"Monday","Tuesday","Wednesday","Thursday","Friday","Saturday","Sunday") -> Tuesday | E5: 41435.785 | F5: - | G5: - | H5: - | I5: - | J5: - | K5: - | L5: =C5-C4 -> 84 | V5: =INT(E5) -> 41435 | W5: =E5-V5 -> 0.78472222 | X5: =C5 -> 41436
A6: 1.33 | B6: - | C6: 41493 | D6: =CHOOSE(WEEKDAY(C6,2),"Monday","Tuesday","Wednesday","Thursday","Friday","Saturday","Sunday") -> Wednesday | E6: - | F6: - | G6: - | H6: - | I6: - | J6: - | K6: - | L6: =C6-C5 -> 57 | X6: =C6 -> 41493
A7: 1.35 | B7: - | C7: 41543 | D7: =CHOOSE(WEEKDAY(C7,2),"Monday","Tuesday","Wednesday","Thursday","Friday","Saturday","Sunday") -> Thursday | E7: - | F7: - | G7: - | H7: - | I7: - | J7: - | K7: - | L7: =C7-C6 -> 50 | X7: =C7 -> 41543
A8: 1.37 | B8: - | C8: 41626 | D8: =CHOOSE(WEEKDAY(C8,2),"Monday","Tuesday","Wednesday","Thursday","Friday","Saturday","Sunday") -> Wednesday | E8: - | F8: - | G8: =Devblogs!FO2 -> 41561 | H8: =Devblogs!FP2 -> Monday | I8: =_xludf.DAYS(G8,C7) -> #NAME? | J8: =_xludf.DAYS(C8,G8) -> #NAME? | K8: - | L8: =C8-C7 -> 83 | X8: =C8 -> 41626 | Y8: =G8 -> 41561
A9: 1.39 | B9: - | C9: 41744 | D9: =CHOOSE(WEEKDAY(C9,2),"Monday","Tuesday","Wednesday","Thursday","Friday","Saturday","Sunday") -> Tuesday | E9: - | F9: - | G9: =Devblogs!FL2 -> 41649 | H9: =Devblogs!FM2 -> Friday | I9: =_xludf.DAYS(G9,C8) -> #NAME? | J9: =_xludf.DAYS(C9,G9) -> #NAME? | K9: - | L9: =C9-C8 -> 118 | X9: =C9-365 -> 41379 | Y9: =G9-365 -> 41284
A10: 1.41 | B10: - | C10: 41774 | D10: =CHOOSE(WEEKDAY(C10,2),"Monday","Tuesday","Wednesday","Thursday","Friday","Saturday","Sunday") -> Thursday | E10: 41773.852 | F10: - | G10: =Devblogs!FI2 -> 41747 | H10: =Devblogs!FJ2 -> Friday | I10: =_xludf.DAYS(G10,C9) -> #NAME? | J10: =_xludf.DAYS(C10,G10) -> #NAME? | K10: - | L10: =C10-C9 -> 30 | V10: =INT(E10) -> 41773 | W10: =E10-V10 -> 0.85208333 | X10: =C10-365 -> 41409 | Y10: =G10-365 -> 41382
A11: 1.43 | B11: - | C11: 41921 | D11: =CHOOSE(WEEKDAY(C11,2),"Monday","Tuesday","Wednesday","Thursday","Friday","Saturday","Sunday") -> Thursday | E11: 41920.778 | F11: - | G11: =Devblogs!FF2 -> 41795 | H11: =Devblogs!FG2 -> Thursday | I11: =_xludf.DAYS(G11,C10) -> #NAME? | J11: =_xludf.DAYS(C11,G11) -> #NAME? | K11: - | L11: =C11-C10 -> 147 | V11: =INT(E11) -> 41920 | W11: =E11-V11 -> 0.77847222 | X11: =C11-365 -> 41556 | Y11: =G11-365 -> 41430
A12: 1.45 | B12: Steel Generals | C12: 41989 | D12: =CHOOSE(WEEKDAY(C12,2),"Monday","Tuesday","Wednesday","Thursday","Friday","Saturday","Sunday") -> Tuesday | E12: 41988.872 | F12: - | G12: =Devblogs!FC2 -> 41941 | H12: =Devblogs!FD2 -> Wednesday | I12: =_xludf.DAYS(G12,C11) -> #NAME? | J12: =_xludf.DAYS(C12,G12) -> #NAME? | K12: - | L12: =C12-C11 -> 68 | V12: =INT(E12) -> 41988 | W12: =E12-V12 -> 0.87222222 | X12: =C12-365 -> 41624 | Y12: =G12-365 -> 41576
A13: 1.47 | B13: Big Guns | C13: 42059 | D13: =CHOOSE(WEEKDAY(C13,2),"Monday","Tuesday","Wednesday","Thursday","Friday","Saturday","Sunday") -> Tuesday | E13: 42058.954 | F13: - | G13: =Devblogs!EZ2 -> 42037 | H13: =Devblogs!FA2 -> Monday | I13: =_xludf.DAYS(G13,C12) -> #NAME? | J13: =_xludf.DAYS(C13,G13) -> #NAME? | K13: - | L13: =C13-C12 -> 70 | V13: =INT(E13) -> 42058 | W13: =E13-V13 -> 0.95416667 | X13: =C13-365*2 -> 41329 | Y13: =G13-365*2 -> 41307
A14: 1.49 | B14: Weapons of Victory | C14: 42124 | D14: =CHOOSE(WEEKDAY(C14,2),"Monday","Tuesday","Wednesday","Thursday","Friday","Saturday","Sunday") -> Thursday | E14: 42123.813 | F14: - | G14: =Devblogs!EW2 -> 42111 | H14: =Devblogs!EX2 -> Friday | I14: =_xludf.DAYS(G14,C13) -> #NAME? | J14: =_xludf.DAYS(C14,G14) -> #NAME? | K14: - | L14: =C14-C13 -> 65 | V14: =INT(E14) -> 42123 | W14: =E14-V14 -> 0.81319444 | X14: =C14-365*2 -> 41394 | Y14: =G14-365*2 -> 41381
A15: 1.51 | B15: Cold Steel | C15: 42185 | D15: =CHOOSE(WEEKDAY(C15,2),"Monday","Tuesday","Wednesday","Thursday","Friday","Saturday","Sunday") -> Tuesday | E15: 42184.913 | F15: - | G15: =Devblogs!ET2 -> 42171 | H15: =Devblogs!EU2 -> Tuesday | I15: =_xludf.DAYS(G15,C14) -> #NAME? | J15: =_xludf.DAYS(C15,G15) -> #NAME? | K15: - | L15: =C15-C14 -> 61 | V15: =INT(E15) -> 42184 | W15: =E15-V15 -> 0.91319444 | X15: =C15-365*2 -> 41455 | Y15: =G15-365*2 -> 41441
A16: 1.53 | B16: Firestorm | C16: 42313 | D16: =CHOOSE(WEEKDAY(C16,2),"Monday","Tuesday","Wednesday","Thursday","Friday","Saturday","Sunday") -> Thursday | E16: 42312.797 | F16: - | G16: =Devblogs!EQ2 -> 42221 | H16: =Devblogs!ER2 -> Wednesday | I16: =_xludf.DAYS(G16,C15) -> #NAME? | J16: =_xludf.DAYS(C16,G16) -> #NAME? | K16: - | L16: =C16-C15 -> 128 | V16: =INT(E16) -> 42312 | W16: =E16-V16 -> 0.79652778 | X16: =C16-365*2 -> 41583 | Y16: =G16-365*2 -> 41491
A17: 1.55 | B17: Royal Armour | C17: 42353 | D17: =CHOOSE(WEEKDAY(C17,2),"Monday","Tuesday","Wednesday","Thursday","Friday","Saturday","Sunday") -> Tuesday | E17: 42352.993 | F17: - | G17: =Devblogs!EN2 -> 42341 | H17: =Devblogs!EO2 -> Thursday | I17: =_xludf.DAYS(G17,C16) -> #NAME? | J17: =_xludf.DAYS(C17,G17) -> #NAME? | K17: - | L17: =C17-C16 -> 40 | V17: =INT(E17) -> 42352 | W17: =E17-V17 -> 0.99305556 | X17: =C17-365*2 -> 41623 | Y17: =G17-365*2 -> 41611
A18: 1.57 | B18: Battle March | C18: 42444 | D18: =CHOOSE(WEEKDAY(C18,2),"Monday","Tuesday","Wednesday","Thursday","Friday","Saturday","Sunday") -> Tuesday | E18: 42443.917 | F18: - | G18: =Devblogs!EK2 -> 42395 | H18: =Devblogs!EL2 -> Tuesday | I18: =_xludf.DAYS(G18,C17) -> #NAME? | J18: =_xludf.DAYS(C18,G18) -> #NAME? | K18: =C18-'Dev servers'!C3 -> 7 | L18: =C18-C17 -> 91 | V18: =INT(E18) -> 42443 | W18: =E18-V18 -> 0.91666667 | X18: =C18-365*2-366 -> 41348 | Y18: =G18-365*3 -> 41300
A19: 1.59 | B19: Flaming Arrows | C19: 42530 | D19: =CHOOSE(WEEKDAY(C19,2),"Monday","Tuesday","Wednesday","Thursday","Friday","Saturday","Sunday") -> Thursday | E19: 42529.797 | F19: - | G19: =Devblogs!EH2 -> 42452 | H19: =Devblogs!EI2 -> Wednesday | I19: =_xludf.DAYS(G19,C18) -> #NAME? | J19: =_xludf.DAYS(C19,G19) -> #NAME? | K19: =C19-'Dev servers'!C5 -> 10 | L19: =C19-C18 -> 86 | V19: =INT(E19) -> 42529 | W19: =E19-V19 -> 0.79652778 | X19: =C19-365*2-366 -> 41434 | Y19: =G19-365*2-366 -> 41356
A20: 1.61 | B20: Road to Glory | C20: 42585 | D20: =CHOOSE(WEEKDAY(C20,2),"Monday","Tuesday","Wednesday","Thursday","Friday","Saturday","Sunday") -> Wednesday | E20: 42584.858 | F20: - | G20: =Devblogs!EE2 -> 42557 | H20: =Devblogs!EF2 -> Wednesday | I20: =_xludf.DAYS(G20,C19) -> #NAME? | J20: =_xludf.DAYS(C20,G20) -> #NAME? | K20: =C20-'Dev servers'!C6 -> 4 | L20: =C20-C19 -> 55 | V20: =INT(E20) -> 42584 | W20: =E20-V20 -> 0.85763889 | X20: =C20-365*2-366 -> 41489 | Y20: =G20-365*2-366 -> 41461
A21: 1.63 | B21: Desert Hunters | C21: 42642 | D21: =CHOOSE(WEEKDAY(C21,2),"Monday","Tuesday","Wednesday","Thursday","Friday","Saturday","Sunday") -> Thursday | E21: 42641.76 | F21: - | G21: =Devblogs!EB2 -> 42615 | H21: =Devblogs!EC2 -> Friday | I21: =_xludf.DAYS(G21,C20) -> #NAME? | J21: =_xludf.DAYS(C21,G21) -> #NAME? | K21: =C21-'Dev servers'!C7 -> 14 | L21: =C21-C20 -> 57 | V21: =INT(E21) -> 42641 | W21: =E21-V21 -> 0.76041667 | X21: =C21-365*2-366 -> 41546 | Y21: =G21-365*2-366 -> 41519
A22: 1.65 | B22: Way of the Samurai | C22: 42724 | D22: =CHOOSE(WEEKDAY(C22,2),"Monday","Tuesday","Wednesday","Thursday","Friday","Saturday","Sunday") -> Tuesday | E22: 42723.876 | F22: - | G22: =Devblogs!DY2 -> 42684 | H22: =Devblogs!DZ2 -> Thursday | I22: =_xludf.DAYS(G22,C21) -> #NAME? | J22: =_xludf.DAYS(C22,G22) -> #NAME? | K22: =C22-'Dev servers'!C8 -> 10 | L22: =C22-C21 -> 82 | V22: =INT(E22) -> 42723 | W22: =E22-V22 -> 0.87638889 | X22: =C22-365*2-366 -> 41628 | Y22: =G22-365*2-366 -> 41588
A23: 1.67 | B23: Assault | C23: 42810 | D23: =CHOOSE(WEEKDAY(C23,2),"Monday","Tuesday","Wednesday","Thursday","Friday","Saturday","Sunday") -> Thursday | E23: 42809.909 | F23: - | G23: =Devblogs!DV2 -> 42780 | H23: =Devblogs!DW2 -> Tuesday | I23: =_xludf.DAYS(G23,C22) -> #NAME? | J23: =_xludf.DAYS(C23,G23) -> #NAME? | K23: =C23-'Dev servers'!C9 -> 5 | L23: =C23-C22 -> 86 | V23: =INT(E23) -> 42809 | W23: =E23-V23 -> 0.90902778 | X23: =C23-365*3-366 -> 41349 | Y23: =G23-365*3-366 -> 41319
A24: 1.69 | B24: Regia Aeronautica | C24: 42880 | D24: =CHOOSE(WEEKDAY(C24,2),"Monday","Tuesday","Wednesday","Thursday","Friday","Saturday","Sunday") -> Thursday | E24: 42879.894 | F24: - | G24: =Devblogs!DS2 -> 42857 | H24: =Devblogs!DT2 -> Tuesday | I24: =_xludf.DAYS(G24,C23) -> #NAME? | J24: =_xludf.DAYS(C24,G24) -> #NAME? | K24: =C24-'Dev servers'!C10 -> 7 | L24: =C24-C23 -> 70 | M24: 0 day diff | N24: 1 day diff | O24: 2 day diff | P24: 3 day diff | Q24: 4 day diff | R24: 5 day diff | S24: 6 day diff | T24: 7 day diff | U24: 7+ day diff | V24: =INT(E24) -> 42879 | W24: =E24-V24 -> 0.89444444 | X24: =C24-365*3-366 -> 41419 | Y24: =G24-365*3-366 -> 41396
A25: 1.71 | B25: New E.R.A. | C25: 42996 | D25: =CHOOSE(WEEKDAY(C25,2),"Monday","Tuesday","Wednesday","Thursday","Friday","Saturday","Sunday") -> Monday | E25: 42996.347 | F25: 42992 | G25: =Devblogs!DP2 -> 42965 | H25: =Devblogs!DQ2 -> Friday | I25: =_xludf.DAYS(G25,C24) -> #NAME? | J25: =_xludf.DAYS(C25,G25) -> #NAME? | K25: =C25-'Dev servers'!C12 -> 4 | L25: =C25-C24 -> 116 | M25: =C25=F25 -> FALSE | N25: =OR(C25+1=F25,C25=F25+1) -> FALSE | O25: =OR(C25+2=F25,C25=F25+2) -> FALSE | P25: =OR(C25+3=F25,C25=F25+3) -> FALSE | Q25: =OR(C25+4=F25,C25=F25+4) -> TRUE | R25: =OR(C25+5=F25,C25=F25+5) -> FALSE | S25: =OR(C25+6=F25,C25=F25+6) -> FALSE | T25: =OR(C25+7=F25,C25=F25+7) -> FALSE | U25: =OR(C25+8<=F25,C25>=F25+8) -> FALSE | V25: =INT(E25) -> 42996 | W25: =E25-V25 -> 0.34722222 | X25: =C25-365*3-366 -> 41535 | Y25: =G25-365*3-366 -> 41504
A26: 1.73 | B26: Vive la France | C26: 43040 | D26: =CHOOSE(WEEKDAY(C26,2),"Monday","Tuesday","Wednesday","Thursday","Friday","Saturday","Sunday") -> Wednesday | E26: 43040.324 | F26: 43035 | G26: =Devblogs!DM2 -> 43019 | H26: =Devblogs!DN2 -> Wednesday | I26: =_xludf.DAYS(G26,C25) -> #NAME? | J26: =_xludf.DAYS(C26,G26) -> #NAME? | K26: =C26-'Dev servers'!C13 -> 4 | L26: =C26-C25 -> 44 | M26: =C26=F26 -> FALSE | N26: =OR(C26+1=F26,C26=F26+1) -> FALSE | O26: =OR(C26+2=F26,C26=F26+2) -> FALSE | P26: =OR(C26+3=F26,C26=F26+3) -> FALSE | Q26: =OR(C26+4=F26,C26=F26+4) -> FALSE | R26: =OR(C26+5=F26,C26=F26+5) -> TRUE | S26: =OR(C26+6=F26,C26=F26+6) -> FALSE | T26: =OR(C26+7=F26,C26=F26+7) -> FALSE | U26: =OR(C26+8<=F26,C26>=F26+8) -> FALSE | V26: =INT(E26) -> 43040 | W26: =E26-V26 -> 0.32430556 | X26: =C26-365*3-366 -> 41579 | Y26: =G26-365*3-366 -> 41558
A27: 1.75 | B27: La Résistance | C27: 43088 | D27: =CHOOSE(WEEKDAY(C27,2),"Monday","Tuesday","Wednesday","Thursday","Friday","Saturday","Sunday") -> Tuesday | E27: 43087.851 | F27: 43087 | G27: =Devblogs!DJ2 -> 43071 | H27: =Devblogs!DK2 -> Saturday | I27: =_xludf.DAYS(G27,C26) -> #NAME? | J27: =_xludf.DAYS(C27,G27) -> #NAME? | K27: =C27-'Dev servers'!C15 -> 3 | L27: =C27-C26 -> 48 | M27: =C27=F27 -> FALSE | N27: =OR(C27+1=F27,C27=F27+1) -> TRUE | O27: =OR(C27+2=F27,C27=F27+2) -> FALSE | P27: =OR(C27+3=F27,C27=F27+3) -> FALSE | Q27: =OR(C27+4=F27,C27=F27+4) -> FALSE | R27: =OR(C27+5=F27,C27=F27+5) -> FALSE | S27: =OR(C27+6=F27,C27=F27+6) -> FALSE | T27: =OR(C27+7=F27,C27=F27+7) -> FALSE | U27: =OR(C27+8<=F27,C27>=F27+8) -> FALSE | V27: =INT(E27) -> 43087 | W27: =E27-V27 -> 0.85138889 | X27: =C27-365*3-366 -> 41627 | Y27: =G27-365*3-366 -> 41610
A28: 1.77 | B28: Advancing Storm | C28: 43173 | D28: =CHOOSE(WEEKDAY(C28,2),"Monday","Tuesday","Wednesday","Thursday","Friday","Saturday","Sunday") -> Wednesday | E28: 43172.837 | F28: 43172 | G28: =Devblogs!DG2 -> 43138 | H28: =Devblogs!DH2 -> Wednesday | I28: =_xludf.DAYS(G28,C27) -> #NAME? | J28: =_xludf.DAYS(C28,G28) -> #NAME? | K28: =C28-'Dev servers'!C17 -> 4 | L28: =C28-C27 -> 85 | M28: =C28=F28 -> FALSE | N28: =OR(C28+1=F28,C28=F28+1) -> TRUE | O28: =OR(C28+2=F28,C28=F28+2) -> FALSE | P28: =OR(C28+3=F28,C28=F28+3) -> FALSE | Q28: =OR(C28+4=F28,C28=F28+4) -> FALSE | R28: =OR(C28+5=F28,C28=F28+5) -> FALSE | S28: =OR(C28+6=F28,C28=F28+6) -> FALSE | T28: =OR(C28+7=F28,C28=F28+7) -> FALSE | U28: =OR(C28+8<=F28,C28>=F28+8) -> FALSE | V28: =INT(E28) -> 43172 | W28: =E28-V28 -> 0.83680556 | X28: =C28-365*4-366 -> 41347 | Y28: =G28-365*4-366 -> 41312
A29: 1.79 | B29: Project X | C29: 43263 | D29: =CHOOSE(WEEKDAY(C29,2),"Monday","Tuesday","Wednesday","Thursday","Friday","Saturday","Sunday") -> Tuesday | E29: 43262.836 | F29: 43257 | G29: =Devblogs!DD2 -> 43231 | H29: =Devblogs!DE2 -> Friday | I29: =_xludf.DAYS(G29,C28) -> #NAME? | J29: =_xludf.DAYS(C29,G29) -> #NAME? | K29: =C29-'Dev servers'!C19 -> 3 | L29: =C29-C28 -> 90 | M29: =C29=F29 -> FALSE | N29: =OR(C29+1=F29,C29=F29+1) -> FALSE | O29: =OR(C29+2=F29,C29=F29+2) -> FALSE | P29: =OR(C29+3=F29,C29=F29+3) -> FALSE | Q29: =OR(C29+4=F29,C29=F29+4) -> FALSE | R29: =OR(C29+5=F29,C29=F29+5) -> FALSE | S29: =OR(C29+6=F29,C29=F29+6) -> TRUE | T29: =OR(C29+7=F29,C29=F29+7) -> FALSE | U29: =OR(C29+8<=F29,C29>=F29+8) -> FALSE | V29: =INT(E29) -> 43262 | W29: =E29-V29 -> 0.83611111 | X29: =C29-365*4-366 -> 41437 | Y29: =G29-365*4-366 -> 41405
A30: 1.81 | B30: The Valkyries | C30: 43362 | D30: =CHOOSE(WEEKDAY(C30,2),"Monday","Tuesday","Wednesday","Thursday","Friday","Saturday","Sunday") -> Wednesday | E30: 43361.835 | F30: 43354 | G30: =Devblogs!DA2 -> 43333 | H30: =Devblogs!DB2 -> Tuesday | I30: =_xludf.DAYS(G30,C29) -> #NAME? | J30: =_xludf.DAYS(C30,G30) -> #NAME? | K30: =C30-'Dev servers'!C22 -> 4 | L30: =C30-C29 -> 99 | M30: =C30=F30 -> FALSE | N30: =OR(C30+1=F30,C30=F30+1) -> FALSE | O30: =OR(C30+2=F30,C30=F30+2) -> FALSE | P30: =OR(C30+3=F30,C30=F30+3) -> FALSE | Q30: =OR(C30+4=F30,C30=F30+4) -> FALSE | R30: =OR(C30+5=F30,C30=F30+5) -> FALSE | S30: =OR(C30+6=F30,C30=F30+6) -> FALSE | T30: =OR(C30+7=F30,C30=F30+7) -> FALSE | U30: =OR(C30+8<=F30,C30>=F30+8) -> TRUE | V30: =INT(E30) -> 43361 | W30: =E30-V30 -> 0.83541667 | X30: =C30-365*4-366 -> 41536 | Y30: =G30-365*4-366 -> 41507
A31: 1.83 | B31: Masters of the Sea | C31: 43396 | D31: =CHOOSE(WEEKDAY(C31,2),"Monday","Tuesday","Wednesday","Thursday","Friday","Saturday","Sunday") -> Tuesday | E31: 43395.84 | F31: 43396 | G31: =Devblogs!CX2 -> 43382 | H31: =Devblogs!CY2 -> Tuesday | I31: =_xludf.DAYS(G31,C30) -> #NAME? | J31: =_xludf.DAYS(C31,G31) -> #NAME? | K31: =C31-'Dev servers'!C23 -> 7 | L31: =C31-C30 -> 34 | M31: =C31=F31 -> TRUE | N31: =OR(C31+1=F31,C31=F31+1) -> FALSE | O31: =OR(C31+2=F31,C31=F31+2) -> FALSE | P31: =OR(C31+3=F31,C31=F31+3) -> FALSE | Q31: =OR(C31+4=F31,C31=F31+4) -> FALSE | R31: =OR(C31+5=F31,C31=F31+5) -> FALSE | S31: =OR(C31+6=F31,C31=F31+6) -> FALSE | T31: =OR(C31+7=F31,C31=F31+7) -> FALSE | U31: =OR(C31+8<=F31,C31>=F31+8) -> FALSE | V31: =INT(E31) -> 43395 | W31: =E31-V31 -> 0.83958333 | X31: =C31-365*4-366 -> 41570 | Y31: =G31-365*4-366 -> 41556
A32: 1.85 | B32: Supersonic | C32: 43451 | D32: =CHOOSE(WEEKDAY(C32,2),"Monday","Tuesday","Wednesday","Thursday","Friday","Saturday","Sunday") -> Monday | E32: 43450.844 | F32: 43452 | G32: =Devblogs!CU2 -> 43427 | H32: =Devblogs!CV2 -> Friday | I32: =_xludf.DAYS(G32,C31) -> #NAME? | J32: =_xludf.DAYS(C32,G32) -> #NAME? | K32: =C32-'Dev servers'!C25 -> 4 | L32: =C32-C31 -> 55 | M32: =C32=F32 -> FALSE | N32: =OR(C32+1=F32,C32=F32+1) -> TRUE | O32: =OR(C32+2=F32,C32=F32+2) -> FALSE | P32: =OR(C32+3=F32,C32=F32+3) -> FALSE | Q32: =OR(C32+4=F32,C32=F32+4) -> FALSE | R32: =OR(C32+5=F32,C32=F32+5) -> FALSE | S32: =OR(C32+6=F32,C32=F32+6) -> FALSE | T32: =OR(C32+7=F32,C32=F32+7) -> FALSE | U32: =OR(C32+8<=F32,C32>=F32+8) -> FALSE | V32: =INT(E32) -> 43450 | W32: =E32-V32 -> 0.84375 | X32: =C32-365*4-366 -> 41625 | Y32: =G32-365*4-366 -> 41601
A33: 1.87 | B33: Locked On | C33: 43536 | D33: =CHOOSE(WEEKDAY(C33,2),"Monday","Tuesday","Wednesday","Thursday","Friday","Saturday","Sunday") -> Tuesday | E33: 43535.868 | F33: 43536 | G33: =Devblogs!CR2 -> 43511 | H33: =Devblogs!CS2 -> Friday | I33: =_xludf.DAYS(G33,C32) -> #NAME? | J33: =_xludf.DAYS(C33,G33) -> #NAME? | K33: =C33-'Dev servers'!C27 -> 6 | L33: =C33-C32 -> 85 | M33: =C33=F33 -> TRUE | N33: =OR(C33+1=F33,C33=F33+1) -> FALSE | O33: =OR(C33+2=F33,C33=F33+2) -> FALSE | P33: =OR(C33+3=F33,C33=F33+3) -> FALSE | Q33: =OR(C33+4=F33,C33=F33+4) -> FALSE | R33: =OR(C33+5=F33,C33=F33+5) -> FALSE | S33: =OR(C33+6=F33,C33=F33+6) -> FALSE | T33: =OR(C33+7=F33,C33=F33+7) -> FALSE | U33: =OR(C33+8<=F33,C33>=F33+8) -> FALSE | V33: =INT(E33) -> 43535 | W33: =E33-V33 -> 0.86805556 | X33: =C33-365*5-366 -> 41345 | Y33: =G33-365*5-366 -> 41320
A34: 1.89 | B34: Imperial Navy | C34: 43614 | D34: =CHOOSE(WEEKDAY(C34,2),"Monday","Tuesday","Wednesday","Thursday","Friday","Saturday","Sunday") -> Wednesday | E34: 43613.794 | F34: 43613 | G34: =Devblogs!CO2 -> 43588 | H34: =Devblogs!CP2 -> Friday | I34: =_xludf.DAYS(G34,C33) -> #NAME? | J34: =_xludf.DAYS(C34,G34) -> #NAME? | K34: =C34-'Dev servers'!C29 -> 4 | L34: =C34-C33 -> 78 | M34: =C34=F34 -> FALSE | N34: =OR(C34+1=F34,C34=F34+1) -> TRUE | O34: =OR(C34+2=F34,C34=F34+2) -> FALSE | P34: =OR(C34+3=F34,C34=F34+3) -> FALSE | Q34: =OR(C34+4=F34,C34=F34+4) -> FALSE | R34: =OR(C34+5=F34,C34=F34+5) -> FALSE | S34: =OR(C34+6=F34,C34=F34+6) -> FALSE | T34: =OR(C34+7=F34,C34=F34+7) -> FALSE | U34: =OR(C34+8<=F34,C34>=F34+8) -> FALSE | V34: =INT(E34) -> 43613 | W34: =E34-V34 -> 0.79375 | X34: =C34-365*5-366 -> 41423 | Y34: =G34-365*5-366 -> 41397
A35: 1.91 | B35: Night Vision | C35: 43719 | D35: =CHOOSE(WEEKDAY(C35,2),"Monday","Tuesday","Wednesday","Thursday","Friday","Saturday","Sunday") -> Wednesday | E35: 43718.794 | F35: 43718 | G35: =Devblogs!CL2 -> 43690 | H35: =Devblogs!CM2 -> Tuesday | I35: =_xludf.DAYS(G35,C34) -> #NAME? | J35: =_xludf.DAYS(C35,G35) -> #NAME? | K35: =C35-'Dev servers'!C31 -> 6 | L35: =C35-C34 -> 105 | M35: =C35=F35 -> FALSE | N35: =OR(C35+1=F35,C35=F35+1) -> TRUE | O35: =OR(C35+2=F35,C35=F35+2) -> FALSE | P35: =OR(C35+3=F35,C35=F35+3) -> FALSE | Q35: =OR(C35+4=F35,C35=F35+4) -> FALSE | R35: =OR(C35+5=F35,C35=F35+5) -> FALSE | S35: =OR(C35+6=F35,C35=F35+6) -> FALSE | T35: =OR(C35+7=F35,C35=F35+7) -> FALSE | U35: =OR(C35+8<=F35,C35>=F35+8) -> FALSE | V35: =INT(E35) -> 43718 | W35: =E35-V35 -> 0.79375 | X35: =C35-365*5-366 -> 41528 | Y35: =G35-365*5-366 -> 41499
A36: 1.93 | B36: Shark Attack | C36: 43767 | D36: =CHOOSE(WEEKDAY(C36,2),"Monday","Tuesday","Wednesday","Thursday","Friday","Saturday","Sunday") -> Tuesday | E36: 43766.797 | F36: 43767 | G36: =Devblogs!CI2 -> 43749 | H36: =Devblogs!CJ2 -> Friday | I36: =_xludf.DAYS(G36,C35) -> #NAME? | J36: =_xludf.DAYS(C36,G36) -> #NAME? | K36: =C36-'Dev servers'!C32 -> 5 | L36: =C36-C35 -> 48 | M36: =C36=F36 -> TRUE | N36: =OR(C36+1=F36,C36=F36+1) -> FALSE | O36: =OR(C36+2=F36,C36=F36+2) -> FALSE | P36: =OR(C36+3=F36,C36=F36+3) -> FALSE | Q36: =OR(C36+4=F36,C36=F36+4) -> FALSE | R36: =OR(C36+5=F36,C36=F36+5) -> FALSE | S36: =OR(C36+6=F36,C36=F36+6) -> FALSE | T36: =OR(C36+7=F36,C36=F36+7) -> FALSE | U36: =OR(C36+8<=F36,C36>=F36+8) -> FALSE | V36: =INT(E36) -> 43766 | W36: =E36-V36 -> 0.79652778 | X36: =C36-365*5-366 -> 41576 | Y36: =G36-365*5-366 -> 41558
A37: 1.95 | B37: Northern Wind | C37: 43816 | D37: =CHOOSE(WEEKDAY(C37,2),"Monday","Tuesday","Wednesday","Thursday","Friday","Saturday","Sunday") -> Tuesday | E37: 43815.838 | F37: 43815 | G37: =Devblogs!CF2 -> 43797 | H37: =Devblogs!CG2 -> Thursday | I37: =_xludf.DAYS(G37,C36) -> #NAME? | J37: =_xludf.DAYS(C37,G37) -> #NAME? | K37: =C37-'Dev servers'!C33 -> 5 | L37: =C37-C36 -> 49 | M37: =C37=F37 -> FALSE | N37: =OR(C37+1=F37,C37=F37+1) -> TRUE | O37: =OR(C37+2=F37,C37=F37+2) -> FALSE | P37: =OR(C37+3=F37,C37=F37+3) -> FALSE | Q37: =OR(C37+4=F37,C37=F37+4) -> FALSE | R37: =OR(C37+5=F37,C37=F37+5) -> FALSE | S37: =OR(C37+6=F37,C37=F37+6) -> FALSE | T37: =OR(C37+7=F37,C37=F37+7) -> FALSE | U37: =OR(C37+8<=F37,C37>=F37+8) -> FALSE | V37: =INT(E37) -> 43815 | W37: =E37-V37 -> 0.83819444 | X37: =C37-365*5-366 -> 41625 | Y37: =G37-365*5-366 -> 41606
A38: 1.97 | B38: Viking Fury | C38: 43906 | D38: =CHOOSE(WEEKDAY(C38,2),"Monday","Tuesday","Wednesday","Thursday","Friday","Saturday","Sunday") -> Monday | E38: 43905.797 | F38: 43900 | G38: =Devblogs!CC2 -> 43881 | H38: =Devblogs!CD2 -> Thursday | I38: =_xludf.DAYS(G38,C37) -> #NAME? | J38: =_xludf.DAYS(C38,G38) -> #NAME? | K38: =C38-'Dev servers'!C35 -> 9 | L38: =C38-C37 -> 90 | M38: =C38=F38 -> FALSE | N38: =OR(C38+1=F38,C38=F38+1) -> FALSE | O38: =OR(C38+2=F38,C38=F38+2) -> FALSE | P38: =OR(C38+3=F38,C38=F38+3) -> FALSE | Q38: =OR(C38+4=F38,C38=F38+4) -> FALSE | R38: =OR(C38+5=F38,C38=F38+5) -> FALSE | S38: =OR(C38+6=F38,C38=F38+6) -> TRUE | T38: =OR(C38+7=F38,C38=F38+7) -> FALSE | U38: =OR(C38+8<=F38,C38>=F38+8) -> FALSE | V38: =INT(E38) -> 43905 | W38: =E38-V38 -> 0.79652778 | X38: =C38-365*5-366*2 -> 41349 | Y38: =G38-365*6-366 -> 41325
A39: 1.99 | B39: Starfighters | C39: 43977 | D39: =CHOOSE(WEEKDAY(C39,2),"Monday","Tuesday","Wednesday","Thursday","Friday","Saturday","Sunday") -> Tuesday | E39: 43976.795 | F39: 43983 | G39: =Devblogs!BZ2 -> 43956 | H39: =Devblogs!CA2 -> Tuesday | I39: =_xludf.DAYS(G39,C38) -> #NAME? | J39: =_xludf.DAYS(C39,G39) -> #NAME? | K39: =C39-'Dev servers'!C37 -> 5 | L39: =C39-C38 -> 71 | M39: =C39=F39 -> FALSE | N39: =OR(C39+1=F39,C39=F39+1) -> FALSE | O39: =OR(C39+2=F39,C39=F39+2) -> FALSE | P39: =OR(C39+3=F39,C39=F39+3) -> FALSE | Q39: =OR(C39+4=F39,C39=F39+4) -> FALSE | R39: =OR(C39+5=F39,C39=F39+5) -> FALSE | S39: =OR(C39+6=F39,C39=F39+6) -> TRUE | T39: =OR(C39+7=F39,C39=F39+7) -> FALSE | U39: =OR(C39+8<=F39,C39>=F39+8) -> FALSE | V39: =INT(E39) -> 43976 | W39: =E39-V39 -> 0.79513889 | X39: =C39-365*5-366*2 -> 41420 | Y39: =G39-365*5-366*2 -> 41399
A40: 1.101 | B40: Raining Fire | C40: 44076 | D40: =CHOOSE(WEEKDAY(C40,2),"Monday","Tuesday","Wednesday","Thursday","Friday","Saturday","Sunday") -> Wednesday | E40: 44075.793 | F40: 44082 | G40: =Devblogs!BW2 -> 44057 | H40: =Devblogs!BX2 -> Friday | I40: =_xludf.DAYS(G40,C39) -> #NAME? | J40: =_xludf.DAYS(C40,G40) -> #NAME? | K40: =C40-'Dev servers'!C39 -> 7 | L40: =C40-C39 -> 99 | M40: =C40=F40 -> FALSE | N40: =OR(C40+1=F40,C40=F40+1) -> FALSE | O40: =OR(C40+2=F40,C40=F40+2) -> FALSE | P40: =OR(C40+3=F40,C40=F40+3) -> FALSE | Q40: =OR(C40+4=F40,C40=F40+4) -> FALSE | R40: =OR(C40+5=F40,C40=F40+5) -> FALSE | S40: =OR(C40+6=F40,C40=F40+6) -> TRUE | T40: =OR(C40+7=F40,C40=F40+7) -> FALSE | U40: =OR(C40+8<=F40,C40>=F40+8) -> FALSE | V40: =INT(E40) -> 44075 | W40: =E40-V40 -> 0.79305556 | X40: =C40-365*5-366*2 -> 41519 | Y40: =G40-365*5-366*2 -> 41500
...

Sheet Custom Loadouts
A1: Custom loadouts | C1: A-10A early | P1: A-10A late | AC1: MiG-23MLA | AJ1: Su-22UM3K | AU1: J8B | BE1: F-104S/ASA | BR1: Mirage F1 C | CB1: Kfir C.2
C2: max load – 7257 kg | J2: max imbalance – 1000 kg | P2: max load – 7257 kg | W2: max imbalance – 1000 kg | AC2: max load – 2000 kg | AG2: max imbalance – 500 kg | AJ2: max load – 3000 kg | AP2: max imbalance – 700 kg | AU2: max load – 4500 kg | AZ2: max imbalance – 1000 kg | BE2: max load – 3400 kg | BL2: max imbalance – 500 kg | BR2: max load – 3000 kg | BW2: max imbalance – 500 kg | CB2: max load – 4295 kg | CG2: max imbalance – 1100 kg
C3: max left load – 4500 kg | J3: max right load – 4500 kg | P3: max left load – 4500 kg | W3: max right load – 4500 kg | AC3: max left load – 500 kg | AG3: max right load – 500 kg | AJ3: max left load – 1500 kg | AP3: max right load – 1500 kg | AU3: max left load – 1500 kg | AZ3: max right load – 1500 kg | BE3: max left load – 2200 kg | BL3: max right load – 2200 kg | BR3: max left load – 1500 kg | BW3: max right load – 1500 kg | CB3: max left load – 1500 kg | CG3: max right load – 1500 kg
C4: slot | D4: 0 | E4: 1 | F4: 2 | G4: 3 | H4: 4 | I4: 5 | J4: 6 | K4: 7 | L4: 8 | M4: 9 | N4: 10 | P4: slot | Q4: 0 | R4: 1 | S4: 2 | T4: 3 | U4: 4 | V4: 5 | W4: 6 | X4: 7 | Y4: 8 | Z4: 9 | AA4: 10 | AC4: slot | AD4: 0 | AE4: 1 | AF4: 2 | AG4: 3 | AH4: 4 | AJ4: slot | AK4: 0 | AL4: 1 | AM4: 2 | AN4: 3 | AO4: 4 | AP4: 5 | AQ4: 6 | AR4: 7 | AS4: 8 | AU4: slot | AV4: 0 | AW4: 1 | AX4: 2 | AY4: 3 | AZ4: 4 | BA4: 5 | BB4: 6 | BC4: 7 | BE4: slot | BF4: 0 | BG4: 1 | BH4: 2 | BI4: 3 | BJ4: 4 | BK4: 5 | BL4: 6 | BM4: 7 | BN4: 8 | BO4: 9 | BP4: 10 | BR4: slot | BS4: 0 | BT4: 1 | BU4: 2 | BV4: 3 | BW4: 4 | BX4: 5 | BY4: 6 | BZ4: 7 | CB4: slot | CC4: 0 | CD4: 1 | CE4: 2 | CF4: 3 | CG4: 4 | CH4: 5 | CI4: 6 | CJ4: 7
A5: List of aircraft: | C5: exempt from imbalance calculations? | D5: Yes | H5: Yes | I5: Yes | J5: Yes | K5: Yes | P5: exempt from imbalance calculations? | Q5: Yes | U5: Yes | V5: Yes | W5: Yes | X5: Yes | AC5: exempt from imbalance calculations? | AD5: Yes | AF5: Yes | AG5: Yes | AJ5: exempt from imbalance calculations? | AK5: Yes | AO5: Yes | AP5: Yes | AU5: exempt from imbalance calculations? | AV5: Yes | AZ5: Yes | BE5: exempt from imbalance calculations? | BF5: Yes | BJ5: Yes | BK5: Yes | BL5: Yes | BM5: Yes | BR5: exempt from imbalance calculations? | BS5: Yes | BW5: Yes | CB5: exempt from imbalance calculations? | CC5: Yes
A6: US | C6: Cannons | D6: GAU-8/A | P6: Cannons | Q6: GAU-8/A | AC6: Cannons | AD6: GSh-23L | AE6: GSh-23L | AH6: GSh-23L | AJ6: Cannons | AK6: NR-30 | AU6: Cannons | AV6: Model 23-3 | BE6: Cannons and missile control systems (AAMs in bold require this) | BF6: empty | BK6: M61 | BR6: Cannons | BS6: DEFA 553 | BV6: DEFA 553 | BX6: DEFA 553 | CB6: Cannons | CC6: DEFA 552A
A7: A-10A early | D7: (866 kg) | Q7: (866 kg) | AD7: (155 kg) | AE7: (155 kg) | AH7: (155 kg) | AK7: (66.5 kg) | AV7: (155 kg) | BK7: (650 kg) | BS7: (150 kg) | BV7: (150 kg) | BX7: (150 kg) | CC7: (150 kg)
A8: A-10A late | D8: GAU-8/A + CM | Q8: GAU-8/A + CM | AD8: GSh-23L + CM | AK8: NR-30 + CM | AV8: Model 23-3 + CM | BF8: CM | BS8: DEFA 553 + CM | CC8: DEFA 552A + CM
A9: F-4C | D9: (866 kg) | Q9: (866 kg) | AD9: (155 kg) | AK9: (66.5 kg) | AV9: (155 kg) | BK9: Aspide control | BS9: (150 kg) | CC9: (150 kg)
A10: F-4E | I10: M61 | J10: M61 | P10: Rockets | S10: 7x Hydra 70 (M247) | T10: 7x Hydra 70 (M247) | U10: 7x Hydra 70 (M247) | X10: 7x Hydra 70 (M247) | Y10: 7x Hydra 70 (M247) | Z10: 7x Hydra 70 (M247) | AC10: Rockets | AE10: 16x S-5K | AF10: 16x S-5K | AG10: 16x S-5K | AH10: 16x S-5K | AN10: GSh-23L | AQ10: GSh-23L | AU10: Rockets | AW10: 7x Model 90-1 HEAT | AX10: 7x Model 90-1 HEAT | BB10: 7x Model 90-1 HEAT | BC10: 7x Model 90-1 HEAT | BK10: (20 kg) | BR10: Rockets | BU10: 18x SNEB Type 23 | BV10: 18x SNEB Type 23 | BX10: 18x SNEB Type 23 | BY10: 18x SNEB Type 23 | CE10: M61 | CI10: M61
A11: F-4J | I11: (650 kg) | J11: (650 kg) | S11: (71.12 kg) | T11: (71.12 kg) | U11: (71.12 kg) | X11: (71.12 kg) | Y11: (71.12 kg) | Z11: (71.12 kg) | AE11: (58.24 kg) | AF11: (58.24 kg) | AG11: (58.24 kg) | AH11: (58.24 kg) | AN11: (155 kg) | AQ11: (155 kg) | AW11: (102.2 kg) | AX11: (102.2 kg) | BB11: (102.2 kg) | BC11: (102.2 kg) | BE11: Rockets | BH11: 19x 2.75-inch FFAR Mk. 4 | BI11: 19x 2.75-inch FFAR Mk. 4 | BN11: 19x 2.75-inch FFAR Mk. 4 | BO11: 19x 2.75-inch FFAR Mk. 4 | BU11: (90.9 kg) | BV11: (90.9 kg) | BX11: (90.9 kg) | BY11: (90.9 kg) | CE11: (650 kg) | CI11: (650 kg)
A12: F-14A (early) | C12: Rockets | F12: 7x Hydra 70 (M247) | G12: 7x Hydra 70 (M247) | H12: 7x Hydra 70 (M247) | K12: 7x Hydra 70 (M247) | L12: 7x Hydra 70 (M247) | M12: 7x Hydra 70 (M247) | T12: 21x Hydra 70 (M247) | U12: 21x Hydra 70 (M247) | X12: 21x Hydra 70 (M247) | Y12: 21x Hydra 70 (M247) | AE12: 32x S-5K | AH12: 32x S-5K | AJ12: Rockets | AL12: 7x S-3K | AO12: 7x S-3K | AP12: 7x S-3K | AS12: 7x S-3K | AU12: Bombs | AX12: 1x 500 lbs Mk. 82 | BB12: 1x 500 lbs Mk. 82 | BH12: (154.28 kg) | BI12: (154.28 kg) | BN12: (154.28 kg) | BO12: (154.28 kg) | BU12: 36x SNEB Type 23 | BV12: 36x SNEB Type 23 | BX12: 36x SNEB Type 23 | BY12: 36x SNEB Type 23 | CB12: Rockets | CE12: 38x 2.75-inch FFAR Mk. 4 | CI12: 38x 2.75-inch FFAR Mk. 4
F13: (71.12 kg) | G13: (71.12 kg) | H13: (71.12 kg) | K13: (71.12 kg) | L13: (71.12 kg) | M13: (71.12 kg) | T13: (213.36 kg) | U13: (213.36 kg) | X13: (213.36 kg) | Y13: (213.36 kg) | AE13: (116.48 kg) | AH13: (116.48 kg) | AL13: (164.5 kg) | AO13: (164.5 kg) | AP13: (164.5 kg) | AS13: (164.5 kg) | AX13: (240.9 kg) | BB13: (240.9 kg) | BH13: 4x 5-inch FFAR Mk. 32 Mod. 0 | BO13: 4x 5-inch FFAR Mk. 32 Mod. 0 | BU13: (181.8 kg) | BV13: (181.8 kg) | BX13: (181.8 kg) | BY13: (181.8 kg) | CE13: (308.56 kg) | CI13: (308.56 kg)
A14: GER | G14: 21x Hydra 70 (M247) | H14: 21x Hydra 70 (M247) | K14: 21x Hydra 70 (M247) | L14: 21x Hydra 70 (M247) | P14: Bombs | R14: 1x 500 lbs Mk. 82 | S14: 1x 500 lbs Mk. 82 | T14: 1x 500 lbs Mk. 82 | U14: 1x 500 lbs Mk. 82 | V14: 1x 500 lbs Mk. 82 | W14: 1x 500 lbs Mk. 82 | X14: 1x 500 lbs Mk. 82 | Y14: 1x 500 lbs Mk. 82 | Z14: 1x 500 lbs Mk. 82 | AA14: 1x 500 lbs Mk. 82 | AE14: 20x S-8KO | AH14: 20x S-8KO | AL14: 32x S-5K | AN14: 32x S-5K | AQ14: 32x S-5K | AS14: 32x S-5K | AZ14: 6x 500 lbs Mk. 82 | BH14: (227.2 kg) | BO14: (227.2 kg) | BR14: Bombs | BU14: 1x 250 kg SAMP Type 25 | BV14: 1x 250 kg SAMP Type 25 | BW14: 1x 250 kg SAMP Type 25 | BX14: 1x 250 kg SAMP Type 25 | BY14: 1x 250 kg SAMP Type 25 | CE14: 8x 5-inch FFAR Mk. 32 Mod. 0 | CI14: 8x 5-inch FFAR Mk. 32 Mod. 0
A15: F-4F (early) | G15: (213.36 kg) | H15: (213.36 kg) | K15: (213.36 kg) | L15: (213.36 kg) | R15: (240.9 kg) | S15: (240.9 kg) | T15: (240.9 kg) | U15: (240.9 kg) | V15: (240.9 kg) | W15: (240.9 kg) | X15: (240.9 kg) | Y15: (240.9 kg) | Z15: (240.9 kg) | AA15: (240.9 kg) | AE15: (226 kg) | AH15: (226 kg) | AL15: (116.48 kg) | AN15: (116.48 kg) | AQ15: (116.48 kg) | AS15: (116.48 kg) | AZ15: (1445.4 kg) | BE15: Bombs | BH15: 1x 500 lbs Mk. 82 | BI15: 1x 500 lbs Mk. 82 | BJ15: 1x 500 lbs Mk. 82 | BM15: 1x 500 lbs Mk. 82 | BN15: 1x 500 lbs Mk. 82 | BO15: 1x 500 lbs Mk. 82 | BU15: (247 kg) | BV15: (247 kg) | BW15: (247 kg) | BX15: (247 kg) | BY15: (247 kg) | CE15: (454.4 kg) | CI15: (454.4 kg)
A16: F-4F (late) | C16: Bombs | E16: 1x 500 lbs Mk. 82 | F16: 1x 500 lbs Mk. 82 | G16: 1x 500 lbs Mk. 82 | H16: 1x 500 lbs Mk. 82 | I16: 1x 500 lbs Mk. 82 | J16: 1x 500 lbs Mk. 82 | K16: 1x 500 lbs Mk. 82 | L16: 1x 500 lbs Mk. 82 | M16: 1x 500 lbs Mk. 82 | N16: 1x 500 lbs Mk. 82 | T16: 3x 500 lbs Mk. 82 | U16: 3x 500 lbs Mk. 82 | X16: 3x 500 lbs Mk. 82 | Y16: 3x 500 lbs Mk. 82 | AE16: 1x S-24B | AF16: 1x S-24B | AG16: 1x S-24B | AH16: 1x S-24B | AL16: 20x S-8KO | AN16: 20x S-8KO | AQ16: 20x S-8KO | AS16: 20x S-8KO | AU16: AAM | AX16: 1x PL5B | AY16: 1x PL5B (stock) | BA16: 1x PL5B (stock) | BB16: 1x PL5B | BH16: (240.9 kg) | BI16: (240.9 kg) | BJ16: (240.9 kg) | BM16: (240.9 kg) | BN16: (240.9 kg) | BO16: (240.9 kg) | BU16: 1x 500 lbs Mk. 82 | BV16: 1x 500 lbs Mk. 82 | BW16: 1x 500 lbs Mk. 82 | BX16: 1x 500 lbs Mk. 82 | BY16: 1x 500 lbs Mk. 82 | CB16: Bombs | CE16: 2x 500 lbs Mk. 82 | CF16: 2x 500 lbs Mk. 82 | CH16: 2x 500 lbs Mk. 82 | CI16: 2x 500 lbs Mk. 82
A17: MiG-23MF | E17: (240.9 kg) | F17: (240.9 kg) | G17: (240.9 kg) | H17: (240.9 kg) | I17: (240.9 kg) | J17: (240.9 kg) | K17: (240.9 kg) | L17: (240.9 kg) | M17: (240.9 kg) | N17: (240.9 kg) | T17: (722.7 kg) | U17: (722.7 kg) | X17: (722.7 kg) | Y17: (722.7 kg) | AE17: (235 kg) | AF17: (235 kg) | AG17: (235 kg) | AH17: (235 kg) | AL17: (226 kg) | AN17: (226 kg) | AQ17: (226 kg) | AS17: (226 kg) | AX17: (84 kg) | AY17: (84 kg) | BA17: (84 kg) | BB17: (84 kg) | BH17: 1x 750 lbs M117 | BI17: 1x 750 lbs M117 | BJ17: 1x 750 lbs M117 | BM17: 1x 750 lbs M117 | BN17: 1x 750 lbs M117 | BO17: 1x 750 lbs M117 | BU17: (250 kg) | BV17: (250 kg) | BW17: (250 kg) | BX17: (250 kg) | BY17: (250 kg) | CE17: (481.8 kg) | CF17: (481.8 kg) | CH17: (481.8 kg) | CI17: (481.8 kg)
A18: MiG-23MLA | G18: 3x 500 lbs Mk. 82 | H18: 3x 500 lbs Mk. 82 | K18: 3x 500 lbs Mk. 82 | L18: 3x 500 lbs Mk. 82 | T18: 1x 2000 lbs Mk. 84 | U18: 1x 2000 lbs Mk. 84 | V18: 1x 2000 lbs Mk. 84 | W18: 1x 2000 lbs Mk. 84 | X18: 1x 2000 lbs Mk. 84 | Y18: 1x 2000 lbs Mk. 84 | AC18: Bombs | AE18: 4x 100 kg OFAB-100-120 | AF18: 4x 100 kg OFAB-100-120 | AG18: 4x 100 kg OFAB-100-120 | AH18: 4x 100 kg OFAB-100-120 | AL18: 1x S-24B | AN18: 1x S-24B | AO18: 1x S-24B | AP18: 1x S-24B | AQ18: 1x S-24B | AS18: 1x S-24B | AX18: 1x Aspide-1A | BB18: 1x Aspide-1A | BH18: (362.42 kg) | BI18: (362.42 kg) | BJ18: (362.42 kg) | BM18: (362.42 kg) | BN18: (362.42 kg) | BO18: (362.42 kg) | BU18: 1x 400 kg SAMP Type 21 | BV18: 1x 400 kg SAMP Type 21 | BW18: 1x 400 kg SAMP Type 21 | BX18: 1x 400 kg SAMP Type 21 | BY18: 1x 400 kg SAMP Type 21 | CE18: 3x 500 lbs Mk. 82 | CI18: 3x 500 lbs Mk. 82
A19: Su-22UM3K | G19: (722.7 kg) | H19: (722.7 kg) | K19: (722.7 kg) | L19: (722.7 kg) | T19: (893.6 kg) | U19: (893.6 kg) | V19: (893.6 kg) | W19: (893.6 kg) | X19: (893.6 kg) | Y19: (893.6 kg) | AE19: (456 kg) | AF19: (456 kg) | AG19: (456 kg) | AH19: (456 kg) | AL19: (235 kg) | AN19: (235 kg) | AO19: (235 kg) | AP19: (235 kg) | AQ19: (235 kg) | AS19: (235 kg) | AX19: (230 kg) | BB19: (230 kg) | BI19: 1x 1000 lbs Mk. 83 | BN19: 1x 1000 lbs Mk. 83 | BU19: (400 kg) | BV19: (400 kg) | BW19: (400 kg) | BX19: (400 kg) | BY19: (400 kg) | CE19: (722.7 kg) | CI19: (722.7 kg)
G20: 1x 2000 lbs Mk. 84 | H20: 1x 2000 lbs Mk. 84 | I20: 1x 2000 lbs Mk. 84 | J20: 1x 2000 lbs Mk. 84 | K20: 1x 2000 lbs Mk. 84 | L20: 1x 2000 lbs Mk. 84 | P20: AGM | T20: 3x AGM-65D | Y20: 3x AGM-65D | AE20: 1x 250 kg FAB-250-M62 | AF20: 1x 250 kg FAB-250-M62 | AG20: 1x 250 kg FAB-250-M62 | AH20: 1x 250 kg FAB-250-M62 | AL20: 1x S-25O | AS20: 1x S-25O | BI20: (446.8 kg) | BN20: (446.8 kg) | BU20: 1x 1000 lbs Mk. 83 | BV20: 1x 1000 lbs Mk. 83 | BW20: 1x 1000 lbs Mk. 83 | BX20: 1x 1000 lbs Mk. 83 | BY20: 1x 1000 lbs Mk. 83 | CG20: 5x 500 lbs Mk. 82
A21: USSR | G21: (893.6 kg) | H21: (893.6 kg) | I21: (893.6 kg) | J21: (893.6 kg) | K21: (893.6 kg) | L21: (893.6 kg) | T21: (680.4 kg) | Y21: (680.4 kg) | AE21: (227 kg) | AF21: (227 kg) | AG21: (227 kg) | AH21: (227 kg) | AL21: (370 kg) | AS21: (370 kg) | BL21: 1x 2000 lbs Mk. 84 | BU21: (500 kg) | BV21: (500 kg) | BW21: (500 kg) | BX21: (500 kg) | BY21: (500 kg) | CG21: (1204.5 kg)
A22: MiG-23M | C22: GBU | G22: 1x GBU-8/B | H22: 1x GBU-8/B | K22: 1x GBU-8/B | L22: 1x GBU-8/B | P22: AAM | R22: 1x AIM-9L (stock) | AA22: 1x AIM-9L (stock) | AE22: 1x 500 kg FAB-500-M62 | AH22: 1x 500 kg FAB-500-M62 | AJ22: Bombs | AN22: 1x 100 kg OFAB-100-120 | AQ22: 1x 100 kg OFAB-100-120 | BL22: (893.6 kg) | BV22: 1x 2000 lbs Mk. 84 | BW22: 1x 2000 lbs Mk. 84 | BX22: 1x 2000 lbs Mk. 84 | CE22: 2x 750 lbs M117 | CF22: 2x 750 lbs M117 | CH22: 2x 750 lbs M117 | CI22: 2x 750 lbs M117
A23: MiG-23MLD | G23: (1027 kg) | H23: (1027 kg) | K23: (1027 kg) | L23: (1027 kg) | R23: (84.46 kg) | AA23: (84.46 kg) | AE23: (508.3 kg) | AH23: (508.3 kg) | AN23: (114 kg) | AQ23: (114 kg) | BE23: AAM | BG23: 1x AIM-9L (stock) | BH23: 1x AIM-9L | BO23: 1x AIM-9L | BP23: 1x AIM-9L (stock) | BV23: (1000 kg) | BW23: (1000 kg) | BX23: (1000 kg) | CE23: (724.84 kg) | CF23: (724.84 kg) | CH23: (724.84 kg) | CI23: (724.84 kg)
A24: MiG-27K | C24: AGM | G24: 3x AGM-65B | L24: 3x AGM-65B | R24: 2x AIM-9L | AA24: 2x AIM-9L | AC24: TGP (AGMs in bold require this) | AG24: 1x Delta-NG | AO24: 4x 100 kg OFAB-100-120 | AP24: 4x 100 kg OFAB-100-120 | BG24: (84.46 kg) | BH24: (84.46 kg) | BO24: (84.46 kg) | BP24: (84.46 kg) | BR24: AAM | BV24: 1x R530E | BW24: 1x R530E | BX24: 1x R530E | CE24: 2x 1000 lbs Mk. 83 | CF24: 2x 1000 lbs Mk. 83 | CH24: 2x 1000 lbs Mk. 83 | CI24: 2x 1000 lbs Mk. 83
A25: MiG-27M | G25: (621 kg) | L25: (621 kg) | R25: (168.92 kg) | AA25: (168.92 kg) | AG25: (20 kg) | AO25: (456 kg) | AP25: (456 kg) | BH25: 1x Aspide-1A | BO25: 1x Aspide-1A | BV25: (193.5 kg) | BW25: (193.5 kg) | BX25: (193.5 kg) | CE25: (893.6 kg) | CF25: (893.6 kg) | CH25: (893.6 kg) | CI25: (893.6 kg)
A26: Su-17M4 | C26: AAM | E26: 1x AIM-9L | N26: 1x AIM-9L | AC26: AGM | AE26: 1x Kh-23M | AF26: 1x R-13M1 | AG26: 1x R-13M1 | AH26: 1x Kh-23M | AL26: 5x 100 kg OFAB-100-120 | AS26: 5x 100 kg OFAB-100-120 | BH26: (230 kg) | BO26: (230 kg) | BT26: 1x R550 Magic 1 (stock) | BZ26: 1x R550 Magic 1 (stock) | CE26: 1x 2000 lbs Mk. 84 | CI26: 1x 2000 lbs Mk. 84
E27: (84.46 kg) | N27: (84.46 kg) | AE27: (289 kg) | AH27: (289 kg) | AL27: (570 kg) | AS27: (570 kg) | BT27: (89 kg) | BZ27: (89 kg) | CE27: (893.6 kg) | CI27: (893.6 kg)
A28: UK | AC28: AAM | AE28: 1x R-13M1 (stock) | AF28: 1x R-13M1 | AG28: 1x R-13M1 | AH28: 1x R-13M1 (stock) | AL28: 1x 250 kg OFAB-250sv | AN28: 1x 250 kg OFAB-250sv | AQ28: 1x 250 kg OFAB-250sv | AS28: 1x 250 kg OFAB-250sv | BT28: 1x R550 Magic 2 | BZ28: 1x R550 Magic 2 | CB28: AAM | CD28: 1x Shafrir 2 (stock) | CJ28: 1x Shafrir 2 (stock)
A29: Phantom FG. 1 | AE29: (90.6 kg) | AF29: (90.6 kg) | AG29: (90.6 kg) | AH29: (90.6 kg) | AL29: (250 kg) | AN29: (250 kg) | AQ29: (250 kg) | AS29: (250 kg) | BT29: (89 kg) | BZ29: (89 kg) | CD29: (93 kg) | CJ29: (93 kg)
A30: Phantom FGR. 2 | AE30: 1x R-60 | AF30: 2x R-60 | AG30: 2x R-60 | AH30: 1x R-60 | AO30: 3x 250 kg OFAB-250sv | AP30: 3x 250 kg OFAB-250sv | BV30: 1x R530 | BW30: 1x R530 | BX30: 1x R530 | CD30: 1x AIM-9D (stock) | CJ30: 1x AIM-9D (stock)
AE31: (44 kg) | AF31: (88 kg) | AG31: (88 kg) | AH31: (44 kg) | AO31: (750 kg) | AP31: (750 kg) | BV31: (193.5 kg) | BW31: (193.5 kg) | BX31: (193.5 kg) | CD31: (88.45 kg) | CJ31: (88.45 kg)
A32: JP | AE32: 1x R-23R | AH32: 1x R-23R | AL32: 1x 500 kg FAB-500-M62 | AS32: 1x 500 kg FAB-500-M62 | BV32: 1x Super 530F | BX32: 1x Super 530F | CD32: 1x AIM-9G | CJ32: 1x AIM-9G
A33: F-4EJ | AE33: (223 kg) | AH33: (223 kg) | AL33: (508.3 kg) | AS33: (508.3 kg) | BV33: (245 kg) | BX33: (245 kg) | CD33: (88.45 kg) | CJ33: (88.45 kg)
A34: F-4EJ Kai | AE34: 1x R-23T | AH34: 1x R-23T | AO34: 2x 500 kg FAB-500-M62 | AP34: 2x 500 kg FAB-500-M62
AE35: (215 kg) | AH35: (215 kg) | AO35: (1016.6 kg) | AP35: (1016.6 kg)
A36: CN | AE36: 1x R-24R | AH36: 1x R-24R | AJ36: TGP (AGMs in bold require this) | AQ36: 1x Delta-NG
A37: J8B | AE37: (244 kg) | AH37: (244 kg) | AQ37: (20 kg)
AE38: 1x R-24T | AH38: 1x R-24T | AJ38: AGM | AL38: 1x S-25L | AS38: 1x S-25L
A39: IT | AE39: (237 kg) | AH39: (237 kg) | AL39: (410 kg) | AS39: (410 kg)
A40: F-104S/ASA | AL40: 1x Kh-23M | AS40: 1x Kh-23M
...

Sheet Leaks
A1: Leaks
A2: Version | B2: Name | C2: Date | D2: Day | E2: First devblog to leak | F2: Leak to release | G2: Image links
A3: =Updates!A55 -> 2.29 | B3: =Updates!B55 -> Sons of Attila | C3: 45160 | D3: =CHOOSE(WEEKDAY(C3,2),"Monday","Tuesday","Wednesday","Thursday","Friday","Saturday","Sunday") -> Tuesday | E3: =_xludf.DAYS(C3,Devblogs!AD2) -> #NAME? | F3: =_xludf.DAYS(Updates!C55,C3) -> #NAME? | G3: [Image]
A4: =Updates!A56 -> 2.31 | B4: =Updates!B56 -> Kings of Battle | C4: 45209 | D4: =CHOOSE(WEEKDAY(C4,2),"Monday","Tuesday","Wednesday","Thursday","Friday","Saturday","Sunday") -> Tuesday | E4: =_xludf.DAYS(C4,Devblogs!AA2) -> #NAME? | F4: =_xludf.DAYS(Updates!C56,C4) -> #NAME? | G4: [Image]
A5: =Updates!A57 -> 2.33 | B5: =Updates!B57 -> Air Superiority | C5: 45254 | D5: =CHOOSE(WEEKDAY(C5,2),"Monday","Tuesday","Wednesday","Thursday","Friday","Saturday","Sunday") -> Friday | E5: =_xludf.DAYS(C5,Devblogs!X2) -> #NAME? | F5: =_xludf.DAYS(Updates!C57,C5) -> #NAME? | G5: [Image]
A6: =Updates!A58 -> 2.35 | B6: =Updates!B58 -> Alpha Strike | C6: 45344 | D6: =CHOOSE(WEEKDAY(C6,2),"Monday","Tuesday","Wednesday","Thursday","Friday","Saturday","Sunday") -> Thursday | E6: =_xludf.DAYS(C6,Devblogs!U2) -> #NAME? | F6: =_xludf.DAYS(Updates!C58,C6) -> #NAME? | G6: [Image]
A7: =Updates!A59 -> 2.37 | B7: =Updates!B59 -> Seek & Destroy | C7: 45416 | D7: =CHOOSE(WEEKDAY(C7,2),"Monday","Tuesday","Wednesday","Thursday","Friday","Saturday","Sunday") -> Saturday | E7: =_xludf.DAYS(C7,Devblogs!R2) -> #NAME? | F7: =_xludf.DAYS(Updates!C59,C7) -> #NAME? | G7: [Image]
A8: =Updates!A60 -> 2.39 | B8: =Updates!B60 -> Dance of Dragons | C8: 45515 | D8: =CHOOSE(WEEKDAY(C8,2),"Monday","Tuesday","Wednesday","Thursday","Friday","Saturday","Sunday") -> Sunday | E8: =_xludf.DAYS(C8,Devblogs!O2) -> #NAME? | F8: =_xludf.DAYS(Updates!C60,C8) -> #NAME? | G8: [Image]
A9: =Updates!A61 -> 2.41 | B9: =Updates!B61 -> Firebirds | C9: 45583 | D9: =CHOOSE(WEEKDAY(C9,2),"Monday","Tuesday","Wednesday","Thursday","Friday","Saturday","Sunday") -> Friday | E9: =_xludf.DAYS(C9,Devblogs!L2) -> #NAME? | F9: =IF(_xludf.DAYS(Updates!C61,C9)>-1,_xludf.DAYS(Updates!C61,C9),0) -> #NAME? | G9: [Image]
A10: =Updates!A62 -> 2.43 | B10: =Updates!B62 -> Storm Warning | C10: 45623 | D10: =CHOOSE(WEEKDAY(C10,2),"Monday","Tuesday","Wednesday","Thursday","Friday","Saturday","Sunday") -> Wednesday | E10: =_xludf.DAYS(C10,Devblogs!I2) -> #NAME? | F10: =IF(_xludf.DAYS(Updates!C62,C10)>-1,_xludf.DAYS(Updates!C62,C10),0) -> #NAME? | G10: [Image]
A11: =Updates!A63 -> 2.45 | B11: =Updates!B63 -> 0 | C11: 45708 | D11: =CHOOSE(WEEKDAY(C11,2),"Monday","Tuesday","Wednesday","Thursday","Friday","Saturday","Sunday") -> Thursday | E11: =_xludf.DAYS(C11,Devblogs!F2) -> #NAME? | F11: =IF(_xludf.DAYS(Updates!C63,C11)>-1,_xludf.DAYS(Updates!C63,C11),0) -> #NAME? | G11: [Image]

Sheet Teasers
A1: Teasers
A2: Version | B2: Name | C2: Date | D2: Time (UTC) | E2: Day | F2: First devblog to teaser | G2: Number of devblogs until teaser*
A3: =Updates!A41 -> 2.1 | B3: =Updates!B41 -> New Power | C3: 44127 | D3: 0.54166667 | E3: =CHOOSE(WEEKDAY(C3,2),"Monday","Tuesday","Wednesday","Thursday","Friday","Saturday","Sunday") -> Friday | F3: =_xludf.DAYS(C3,Devblogs!BT2) -> #NAME? | G3: =IF(COUNTIF(Devblogs!BT2:BT45,"<"&C3)=COUNTIF(Devblogs!BT2:BT45,"<="&C3),COUNTIF(Devblogs!BT2:BT45,"<"&C3),CONCATENATE(COUNTIF(Devblogs!BT2:BT45,"<"&C3), " - ",COUNTIF(Devblogs!BT2:BT45,"<="&C3))) -> 3
A4: =Updates!A43 -> 2.5 | B4: =Updates!B43 -> Ixwa Strike | C4: 44245 | D4: 0.625 | E4: =CHOOSE(WEEKDAY(C4,2),"Monday","Tuesday","Wednesday","Thursday","Friday","Saturday","Sunday") -> Thursday | F4: =_xludf.DAYS(C4,Devblogs!BN2) -> #NAME? | G4: =IF(COUNTIF(Devblogs!BN2:BN45,"<"&C4)=COUNTIF(Devblogs!BN2:BN45,"<="&C4),COUNTIF(Devblogs!BN2:BN45,"<"&C4),CONCATENATE(COUNTIF(Devblogs!BN2:BN45,"<"&C4), " - ",COUNTIF(Devblogs!BN2:BN45,"<="&C4))) -> 3 - 5
A5: =Updates!A44 -> 2.7 | B5: =Updates!B44 -> Red Skies | C5: 44336 | D5: 0.58333333 | E5: =CHOOSE(WEEKDAY(C5,2),"Monday","Tuesday","Wednesday","Thursday","Friday","Saturday","Sunday") -> Thursday | F5: =_xludf.DAYS(C5,Devblogs!BK2) -> #NAME? | G5: =IF(COUNTIF(Devblogs!BK2:BK45,"<"&C5)=COUNTIF(Devblogs!BK2:BK45,"<="&C5),COUNTIF(Devblogs!BK2:BK45,"<"&C5),CONCATENATE(COUNTIF(Devblogs!BK2:BK45,"<"&C5), " - ",COUNTIF(Devblogs!BK2:BK45,"<="&C5))) -> 5 - 6
A6: =Updates!A45 -> 2.9 | B6: =Updates!B45 -> Direct Hit | C6: 44432 | D6: 0.75 | E6: =CHOOSE(WEEKDAY(C6,2),"Monday","Tuesday","Wednesday","Thursday","Friday","Saturday","Sunday") -> Tuesday | F6: =_xludf.DAYS(C6,Devblogs!BH2) -> #NAME? | G6: =IF(COUNTIF(Devblogs!BH2:BH45,"<"&C6)=COUNTIF(Devblogs!BH2:BH45,"<="&C6),COUNTIF(Devblogs!BH2:BH45,"<"&C6),CONCATENATE(COUNTIF(Devblogs!BH2:BH45,"<"&C6), " - ",COUNTIF(Devblogs!BH2:BH45,"<="&C6))) -> 4 - 5
A7: =Updates!A46 -> 2.11 | B7: =Updates!B46 -> Ground Breaking | C7: 44481 | D7: 0.66666667 | E7: =CHOOSE(WEEKDAY(C7,2),"Monday","Tuesday","Wednesday","Thursday","Friday","Saturday","Sunday") -> Tuesday | F7: =_xludf.DAYS(C7,Devblogs!BE2) -> #NAME? | G7: =IF(COUNTIF(Devblogs!BE2:BE45,"<"&C7)=COUNTIF(Devblogs!BE2:BE45,"<="&C7),COUNTIF(Devblogs!BE2:BE45,"<"&C7),CONCATENATE(COUNTIF(Devblogs!BE2:BE45,"<"&C7), " - ",COUNTIF(Devblogs!BE2:BE45,"<="&C7))) -> 2 - 3
A8: =Updates!A47 -> 2.13 | B8: =Updates!B47 -> Winged Lions | C8: 44532 | D8: 0.66666667 | E8: =CHOOSE(WEEKDAY(C8,2),"Monday","Tuesday","Wednesday","Thursday","Friday","Saturday","Sunday") -> Thursday | F8: =_xludf.DAYS(C8,Devblogs!BB2) -> #NAME? | G8: =IF(COUNTIF(Devblogs!BB2:BB45,"<"&C8)=COUNTIF(Devblogs!BB2:BB45,"<="&C8),COUNTIF(Devblogs!BB2:BB45,"<"&C8),CONCATENATE(COUNTIF(Devblogs!BB2:BB45,"<"&C8), " - ",COUNTIF(Devblogs!BB2:BB45,"<="&C8))) -> 3 - 5
A9: =Updates!A48 -> 2.15 | B9: =Updates!B48 -> Wind of Change | C9: 44630 | D9: 0.625 | E9: =CHOOSE(WEEKDAY(C9,2),"Monday","Tuesday","Wednesday","Thursday","Friday","Saturday","Sunday") -> Thursday | F9: =_xludf.DAYS(C9,Devblogs!AY2) -> #NAME? | G9: =IF(COUNTIF(Devblogs!AY2:AY45,"<"&C9)=COUNTIF(Devblogs!AY2:AY45,"<="&C9),COUNTIF(Devblogs!AY2:AY45,"<"&C9),CONCATENATE(COUNTIF(Devblogs!AY2:AY45,"<"&C9), " - ",COUNTIF(Devblogs!AY2:AY45,"<="&C9))) -> 4 - 6
A10: =Updates!A49 -> 2.17 | B10: =Updates!B49 -> Danger Zone | C10: 44707 | D10: 0.66666667 | E10: =CHOOSE(WEEKDAY(C10,2),"Monday","Tuesday","Wednesday","Thursday","Friday","Saturday","Sunday") -> Thursday | F10: =_xludf.DAYS(C10,Devblogs!AV2) -> #NAME? | G10: =IF(COUNTIF(Devblogs!AV2:AV45,"<"&C10)=COUNTIF(Devblogs!AV2:AV45,"<="&C10),COUNTIF(Devblogs!AV2:AV45,"<"&C10),CONCATENATE(COUNTIF(Devblogs!AV2:AV45,"<"&C10), " - ",COUNTIF(Devblogs!AV2:AV45,"<="&C10))) -> 6 - 8
A11: =CONCATENATE(Updates!A50," #1") -> 2.19 #1 | B11: =Updates!B50 -> Drone Age | C11: 44802 | D11: 0.6875 | E11: =CHOOSE(WEEKDAY(C11,2),"Monday","Tuesday","Wednesday","Thursday","Friday","Saturday","Sunday") -> Monday | F11: =_xludf.DAYS(C11,Devblogs!AS2) -> #NAME? | G11: =IF(COUNTIF(Devblogs!AS2:AS45,"<"&C11)=COUNTIF(Devblogs!AS2:AS45,"<="&C11),COUNTIF(Devblogs!AS2:AS45,"<"&C11),CONCATENATE(COUNTIF(Devblogs!AS2:AS45,"<"&C11), " - ",COUNTIF(Devblogs!AS2:AS45,"<="&C11))) -> 8 - 9
A12: =CONCATENATE(Updates!A50," #2") -> 2.19 #2 | C12: 44805 | D12: 0.81944444 | E12: =CHOOSE(WEEKDAY(C12,2),"Monday","Tuesday","Wednesday","Thursday","Friday","Saturday","Sunday") -> Thursday | F12: =_xludf.DAYS(C12,Devblogs!AS2) -> #NAME? | G12: =IF(COUNTIF(Devblogs!AS2:AS45,"<"&C12)=COUNTIF(Devblogs!AS2:AS45,"<="&C12),COUNTIF(Devblogs!AS2:AS45,"<"&C12),CONCATENATE(COUNTIF(Devblogs!AS2:AS45,"<"&C12), " - ",COUNTIF(Devblogs!AS2:AS45,"<="&C12))) -> 12
A13: =Updates!A51 -> 2.21 | B13: =Updates!B51 -> Fire and Ice | C13: 44847 | D13: 0.68611111 | E13: =CHOOSE(WEEKDAY(C13,2),"Monday","Tuesday","Wednesday","Thursday","Friday","Saturday","Sunday") -> Thursday | F13: =_xludf.DAYS(C13,Devblogs!AP2) -> #NAME? | G13: =IF(COUNTIF(Devblogs!AP2:AP45,"<"&C13)=COUNTIF(Devblogs!AP2:AP45,"<="&C13),COUNTIF(Devblogs!AP2:AP45,"<"&C13),CONCATENATE(COUNTIF(Devblogs!AP2:AP45,"<"&C13), " - ",COUNTIF(Devblogs!AP2:AP45,"<="&C13))) -> 1 - 2
A14: =Updates!A52 -> 2.23 | B14: =Updates!B52 -> Apex Predators | C14: 44903 | D14: 0.79513889 | E14: =CHOOSE(WEEKDAY(C14,2),"Monday","Tuesday","Wednesday","Thursday","Friday","Saturday","Sunday") -> Thursday | F14: =_xludf.DAYS(C14,Devblogs!AM2) -> #NAME? | G14: =IF(COUNTIF(Devblogs!AM2:AM45,"<"&C14)=COUNTIF(Devblogs!AM2:AM45,"<="&C14),COUNTIF(Devblogs!AM2:AM45,"<"&C14),CONCATENATE(COUNTIF(Devblogs!AM2:AM45,"<"&C14), " - ",COUNTIF(Devblogs!AM2:AM45,"<="&C14))) -> 5 - 6
A15: =Updates!A53 -> 2.25 | B15: =Updates!B53 -> Sky Guardians | C15: 44980 | D15: 0.72916667 | E15: =CHOOSE(WEEKDAY(C15,2),"Monday","Tuesday","Wednesday","Thursday","Friday","Saturday","Sunday") -> Thursday | F15: =IF(_xludf.DAYS(C15,Devblogs!AJ2)>-1,_xludf.DAYS(C15,Devblogs!AJ2),0) -> #NAME? | G15: =IF(COUNTIF(Devblogs!AJ2:AJ45,"<"&C15)=COUNTIF(Devblogs!AJ2:AJ45,"<="&C15),COUNTIF(Devblogs!AJ2:AJ45,"<"&C15),CONCATENATE(COUNTIF(Devblogs!AJ2:AJ45,"<"&C15), " - ",COUNTIF(Devblogs!AJ2:AJ45,"<="&C15))) -> 9
A16: =Updates!A54 -> 2.27 | B16: =Updates!B54 -> La Royale | C16: 45064 | D16: 0.70833333 | E16: =CHOOSE(WEEKDAY(C16,2),"Monday","Tuesday","Wednesday","Thursday","Friday","Saturday","Sunday") -> Thursday | F16: =IF(_xludf.DAYS(C16,Devblogs!AG2)>-1,_xludf.DAYS(C16,Devblogs!AG2),0) -> #NAME? | G16: =IF(COUNTIF(Devblogs!AG2:AG45,"<"&C16)=COUNTIF(Devblogs!AG2:AG45,"<="&C16),COUNTIF(Devblogs!AG2:AG45,"<"&C16),CONCATENATE(COUNTIF(Devblogs!AG2:AG45,"<"&C16), " - ",COUNTIF(Devblogs!AG2:AG45,"<="&C16))) -> 11 - 12
A17: =Updates!A55 -> 2.29 | B17: =Updates!B55 -> Sons of Attila | C17: 45169 | D17: 0.79166667 | E17: =CHOOSE(WEEKDAY(C17,2),"Monday","Tuesday","Wednesday","Thursday","Friday","Saturday","Sunday") -> Thursday | F17: =IF(_xludf.DAYS(C17,Devblogs!AD2)>-1,_xludf.DAYS(C17,Devblogs!AD2),0) -> #NAME? | G17: =IF(COUNTIF(Devblogs!AD2:AD45,"<"&C17)=COUNTIF(Devblogs!AD2:AD45,"<="&C17),COUNTIF(Devblogs!AD2:AD45,"<"&C17),CONCATENATE(COUNTIF(Devblogs!AD2:AD45,"<"&C17), " - ",COUNTIF(Devblogs!AD2:AD45,"<="&C17))) -> 8 - 9
A18: =Updates!A56 -> 2.31 | B18: =Updates!B56 -> Kings of Battle | C18: 45218 | D18: 0.82361111 | E18: =CHOOSE(WEEKDAY(C18,2),"Monday","Tuesday","Wednesday","Thursday","Friday","Saturday","Sunday") -> Thursday | F18: =IF(_xludf.DAYS(C18,Devblogs!AA2)>-1,_xludf.DAYS(C18,Devblogs!AA2),0) -> #NAME? | G18: =IF(COUNTIF(Devblogs!AA2:AA45,"<"&C18)=COUNTIF(Devblogs!AA2:AA45,"<="&C18),COUNTIF(Devblogs!AA2:AA45,"<"&C18),CONCATENATE(COUNTIF(Devblogs!AA2:AA45,"<"&C18), " - ",COUNTIF(Devblogs!AA2:AA45,"<="&C18))) -> 2
A19: =Updates!A57 -> 2.33 | B19: =Updates!B57 -> Air Superiority | C19: 45266 | D19: 0.90347222 | E19: =CHOOSE(WEEKDAY(C19,2),"Monday","Tuesday","Wednesday","Thursday","Friday","Saturday","Sunday") -> Wednesday | F19: =IF(_xludf.DAYS(C19,Devblogs!X2)>-1,_xludf.DAYS(C19,Devblogs!X2),0) -> #NAME? | G19: =IF(COUNTIF(Devblogs!X2:X45,"<"&C19)=COUNTIF(Devblogs!X2:X45,"<="&C19),COUNTIF(Devblogs!X2:X45,"<"&C19),CONCATENATE(COUNTIF(Devblogs!X2:X45,"<"&C19), " - ",COUNTIF(Devblogs!X2:X45,"<="&C19))) -> 3 - 4
A20: =Updates!A58 -> 2.35 | B20: =Updates!B58 -> Alpha Strike | C20: 45351 | D20: 0.72361111 | E20: =CHOOSE(WEEKDAY(C20,2),"Monday","Tuesday","Wednesday","Thursday","Friday","Saturday","Sunday") -> Thursday | F20: =IF(_xludf.DAYS(C20,Devblogs!U2)>-1,_xludf.DAYS(C20,Devblogs!U2),0) -> #NAME? | G20: =IF(COUNTIF(Devblogs!U2:U45,"<"&C20)=COUNTIF(Devblogs!U2:U45,"<="&C20),COUNTIF(Devblogs!U2:U45,"<"&C20),CONCATENATE(COUNTIF(Devblogs!U2:U45,"<"&C20), " - ",COUNTIF(Devblogs!U2:U45,"<="&C20))) -> 4 - 5
A21: =Updates!A59 -> 2.37 | B21: =Updates!B59 -> Seek & Destroy | C21: 45442 | D21: 0.77430556 | E21: =CHOOSE(WEEKDAY(C21,2),"Monday","Tuesday","Wednesday","Thursday","Friday","Saturday","Sunday") -> Thursday | F21: =IF(_xludf.DAYS(C21,Devblogs!R$2)>-1,_xludf.DAYS(C21,Devblogs!R$2),0) -> #NAME? | G21: =IF(COUNTIF(Devblogs!R$2:R$45,"<"&C21)=COUNTIF(Devblogs!R$2:R$45,"<="&C21),COUNTIF(Devblogs!R$2:R$45,"<"&C21),CONCATENATE(COUNTIF(Devblogs!R$2:R$45,"<"&C21), " - ",COUNTIF(Devblogs!R$2:R$45,"<="&C21))) -> 6 - 7
A22: =Updates!A60 -> 2.39 | B22: =Updates!B60 -> Dance of Dragons | C22: 45533 | D22: 0.81805556 | E22: =CHOOSE(WEEKDAY(C22,2),"Monday","Tuesday","Wednesday","Thursday","Friday","Saturday","Sunday") -> Thursday | F22: =IF(_xludf.DAYS(C22,Devblogs!O$2)>-1,_xludf.DAYS(C22,Devblogs!O$2),0) -> #NAME? | G22: =IF(COUNTIF(Devblogs!O$2:O$45,"<"&C22)=COUNTIF(Devblogs!O$2:O$45,"<="&C22),COUNTIF(Devblogs!O$2:O$45,"<"&C22),CONCATENATE(COUNTIF(Devblogs!O$2:O$45,"<"&C22), " - ",COUNTIF(Devblogs!O$2:O$45,"<="&C22))) -> 4
A23: =Updates!A61 -> 2.41 | B23: =Updates!B61 -> Firebirds | C23: 45589 | D23: 0.72152778 | E23: =CHOOSE(WEEKDAY(C23,2),"Monday","Tuesday","Wednesday","Thursday","Friday","Saturday","Sunday") -> Thursday | F23: =IF(_xludf.DAYS(C23,Devblogs!L$2)>-1,_xludf.DAYS(C23,Devblogs!L$2),0) -> #NAME? | G23: =IF(COUNTIF(Devblogs!L$2:L$45,"<"&C23)=COUNTIF(Devblogs!L$2:L$45,"<="&C23),COUNTIF(Devblogs!L$2:L$45,"<"&C23),CONCATENATE(COUNTIF(Devblogs!L$2:L$45,"<"&C23), " - ",COUNTIF(Devblogs!L$2:L$45,"<="&C23))) -> 5 - 6
A24: =Updates!A62 -> 2.43 | B24: =Updates!B62 -> Storm Warning | C24: 45635 | D24: 0.70138889 | E24: =CHOOSE(WEEKDAY(C24,2),"Monday","Tuesday","Wednesday","Thursday","Friday","Saturday","Sunday") -> Monday | F24: =IF(_xludf.DAYS(C24,Devblogs!I$2)>-1,_xludf.DAYS(C24,Devblogs!I$2),0) -> #NAME? | G24: =IF(COUNTIF(Devblogs!I$2:I$45,"<"&C24)=COUNTIF(Devblogs!I$2:I$45,"<="&C24),COUNTIF(Devblogs!I$2:I$45,"<"&C24),CONCATENATE(COUNTIF(Devblogs!I$2:I$45,"<"&C24), " - ",COUNTIF(Devblogs!I$2:I$45,"<="&C24))) -> 2 - 4
A25: =Updates!A63 -> 2.45 | B25: =Updates!B63 -> 0 | F25: =IF(_xludf.DAYS(C25,Devblogs!L$2)>-1,_xludf.DAYS(C25,Devblogs!L$2),0) -> #NAME? | G25: =IF(COUNTIF(Devblogs!L$2:L$45,"<"&C25)=COUNTIF(Devblogs!L$2:L$45,"<="&C25),COUNTIF(Devblogs!L$2:L$45,"<"&C25),CONCATENATE(COUNTIF(Devblogs!L$2:L$45,"<"&C25), " - ",COUNTIF(Devblogs!L$2:L$45,"<="&C25))) -> 0
B28: Release date day of week | F28: Average release time: | G28: =AVERAGE(D3:D27) -> 0.71856061
B29: Monday: | C29: =COUNTIF(E3:E27,"Monday") -> 2 | D29: =C29/SUM($C$29:$C$35) -> 0.090909091
B30: Tuesday: | C30: =COUNTIF(E3:E27,"Tuesday") -> 2 | D30: =C30/SUM($C$29:$C$35) -> 0.090909091
B31: Wednesday: | C31: =COUNTIF(E3:E27,"Wednesday") -> 1 | D31: =C31/SUM($C$29:$C$35) -> 0.045454545
B32: Thursday: | C32: =COUNTIF(E3:E27,"Thursday") -> 16 | D32: =C32/SUM($C$29:$C$35) -> 0.72727273
B33: Friday: | C33: =COUNTIF(E3:E27,"Friday") -> 1 | D33: =C33/SUM($C$29:$C$35) -> 0.045454545
B34: Saturday: | C34: =COUNTIF(E3:E27,"Saturday") -> 0 | D34: =C34/SUM($C$29:$C$35) -> 0 | G34: *: discrepancy is due to the inclusion of same day devblogs
B35: Sunday: | C35: =COUNTIF(E3:E27,"Sunday") -> 0 | D35: =C35/SUM($C$29:$C$35) -> 0

Sheet Dev streams
A1: Dev streams
A2: Version | B2: Name | C2: Date | D2: Day | E2: First devblog to stream | F2: Number of devblogs until stream*
A3: =Updates!A33 -> 1.87 | B3: =Updates!B33 -> Locked On | C3: 43523 | D3: =CHOOSE(WEEKDAY(C3,2),"Monday","Tuesday","Wednesday","Thursday","Friday","Saturday","Sunday") -> Wednesday | E3: =_xludf.DAYS(C3,Devblogs!CR2) -> #NAME? | F3: =IF(COUNTIF(Devblogs!CR2:CR45,"<"&C3)=COUNTIF(Devblogs!CR2:CR45,"<="&C3),COUNTIF(Devblogs!CR2:CR45,"<"&C3),CONCATENATE(COUNTIF(Devblogs!CR2:CR45,"<"&C3), " - ",COUNTIF(Devblogs!CR2:CR45,"<="&C3))) -> 9 - 10
A4: =Updates!A34 -> 1.89 | B4: =Updates!B34 -> Imperial Navy | C4: 43602 | D4: =CHOOSE(WEEKDAY(C4,2),"Monday","Tuesday","Wednesday","Thursday","Friday","Saturday","Sunday") -> Friday | E4: =_xludf.DAYS(C4,Devblogs!CO2) -> #NAME? | F4: =IF(COUNTIF(Devblogs!CO2:CO45,"<"&C4)=COUNTIF(Devblogs!CO2:CO45,"<="&C4),COUNTIF(Devblogs!CO2:CO45,"<"&C4),CONCATENATE(COUNTIF(Devblogs!CO2:CO45,"<"&C4), " - ",COUNTIF(Devblogs!CO2:CO45,"<="&C4))) -> 10 - 12
A5: =Updates!A35 -> 1.91 | B5: =Updates!B35 -> Night Vision | C5: 43707 | D5: =CHOOSE(WEEKDAY(C5,2),"Monday","Tuesday","Wednesday","Thursday","Friday","Saturday","Sunday") -> Friday | E5: =_xludf.DAYS(C5,Devblogs!CL2) -> #NAME? | F5: =IF(COUNTIF(Devblogs!CL2:CL45,"<"&C5)=COUNTIF(Devblogs!CL2:CL45,"<="&C5),COUNTIF(Devblogs!CL2:CL45,"<"&C5),CONCATENATE(COUNTIF(Devblogs!CL2:CL45,"<"&C5), " - ",COUNTIF(Devblogs!CL2:CL45,"<="&C5))) -> 15 - 16
A6: =Updates!A36 -> 1.93 | B6: =Updates!B36 -> Shark Attack | C6: 43762 | D6: =CHOOSE(WEEKDAY(C6,2),"Monday","Tuesday","Wednesday","Thursday","Friday","Saturday","Sunday") -> Thursday | E6: =_xludf.DAYS(C6,Devblogs!CI2) -> #NAME? | F6: =IF(COUNTIF(Devblogs!CI2:CI45,"<"&C6)=COUNTIF(Devblogs!CI2:CI45,"<="&C6),COUNTIF(Devblogs!CI2:CI45,"<"&C6),CONCATENATE(COUNTIF(Devblogs!CI2:CI45,"<"&C6), " - ",COUNTIF(Devblogs!CI2:CI45,"<="&C6))) -> 8 - 10
A7: =Updates!A37 -> 1.95 | B7: =Updates!B37 -> Northern Wind | C7: 43811 | D7: =CHOOSE(WEEKDAY(C7,2),"Monday","Tuesday","Wednesday","Thursday","Friday","Saturday","Sunday") -> Thursday | E7: =_xludf.DAYS(C7,Devblogs!CF2) -> #NAME? | F7: =IF(COUNTIF(Devblogs!CF2:CF45,"<"&C7)=COUNTIF(Devblogs!CF2:CF45,"<="&C7),COUNTIF(Devblogs!CF2:CF45,"<"&C7),CONCATENATE(COUNTIF(Devblogs!CF2:CF45,"<"&C7), " - ",COUNTIF(Devblogs!CF2:CF45,"<="&C7))) -> 13 - 14
A8: =Updates!A38 -> 1.97 | B8: =Updates!B38 -> Viking Fury | C8: 43893 | D8: =CHOOSE(WEEKDAY(C8,2),"Monday","Tuesday","Wednesday","Thursday","Friday","Saturday","Sunday") -> Tuesday | E8: =_xludf.DAYS(C8,Devblogs!CC2) -> #NAME? | F8: =IF(COUNTIF(Devblogs!CC2:CC45,"<"&C8)=COUNTIF(Devblogs!CC2:CC45,"<="&C8),COUNTIF(Devblogs!CC2:CC45,"<"&C8),CONCATENATE(COUNTIF(Devblogs!CC2:CC45,"<"&C8), " - ",COUNTIF(Devblogs!CC2:CC45,"<="&C8))) -> 13 - 14
A9: =Updates!A39 -> 1.99 | B9: =Updates!B39 -> Starfighters | C9: 43966 | D9: =CHOOSE(WEEKDAY(C9,2),"Monday","Tuesday","Wednesday","Thursday","Friday","Saturday","Sunday") -> Friday | E9: =_xludf.DAYS(C9,Devblogs!BZ2) -> #NAME? | F9: =IF(COUNTIF(Devblogs!BZ2:BZ45,"<"&C9)=COUNTIF(Devblogs!BZ2:BZ45,"<="&C9),COUNTIF(Devblogs!BZ2:BZ45,"<"&C9),CONCATENATE(COUNTIF(Devblogs!BZ2:BZ45,"<"&C9), " - ",COUNTIF(Devblogs!BZ2:BZ45,"<="&C9))) -> 8 - 10
A10: =Updates!A40 -> 1.101 | B10: =Updates!B40 -> Raining Fire | C10: 44064 | D10: =CHOOSE(WEEKDAY(C10,2),"Monday","Tuesday","Wednesday","Thursday","Friday","Saturday","Sunday") -> Friday | E10: =_xludf.DAYS(C10,Devblogs!BW2) -> #NAME? | F10: =IF(COUNTIF(Devblogs!BW2:BW45,"<"&C10)=COUNTIF(Devblogs!BW2:BW45,"<="&C10),COUNTIF(Devblogs!BW2:BW45,"<"&C10),CONCATENATE(COUNTIF(Devblogs!BW2:BW45,"<"&C10), " - ",COUNTIF(Devblogs!BW2:BW45,"<="&C10))) -> 5
A11: =Updates!A41 -> 2.1 | B11: =Updates!B41 -> New Power | C11: 44134 | D11: =CHOOSE(WEEKDAY(C11,2),"Monday","Tuesday","Wednesday","Thursday","Friday","Saturday","Sunday") -> Friday | E11: =_xludf.DAYS(C11,Devblogs!BT2) -> #NAME? | F11: =IF(COUNTIF(Devblogs!BT2:BT45,"<"&C11)=COUNTIF(Devblogs!BT2:BT45,"<="&C11),COUNTIF(Devblogs!BT2:BT45,"<"&C11),CONCATENATE(COUNTIF(Devblogs!BT2:BT45,"<"&C11), " - ",COUNTIF(Devblogs!BT2:BT45,"<="&C11))) -> 10 - 11
A12: =Updates!A42 -> 2.3 | B12: =Updates!B42 -> Hot Tracks | C12: 44176 | D12: =CHOOSE(WEEKDAY(C12,2),"Monday","Tuesday","Wednesday","Thursday","Friday","Saturday","Sunday") -> Friday | E12: =_xludf.DAYS(C12,Devblogs!BQ2) -> #NAME? | F12: =IF(COUNTIF(Devblogs!BQ2:BQ45,"<"&C12)=COUNTIF(Devblogs!BQ2:BQ45,"<="&C12),COUNTIF(Devblogs!BQ2:BQ45,"<"&C12),CONCATENATE(COUNTIF(Devblogs!BQ2:BQ45,"<"&C12), " - ",COUNTIF(Devblogs!BQ2:BQ45,"<="&C12))) -> 4 - 5
A13: =Updates!A43 -> 2.5 | B13: =Updates!B43 -> Ixwa Strike | C13: 44247 | D13: =CHOOSE(WEEKDAY(C13,2),"Monday","Tuesday","Wednesday","Thursday","Friday","Saturday","Sunday") -> Saturday | E13: =_xludf.DAYS(C13,Devblogs!BN2) -> #NAME? | F13: =IF(COUNTIF(Devblogs!BN2:BN45,"<"&C13)=COUNTIF(Devblogs!BN2:BN45,"<="&C13),COUNTIF(Devblogs!BN2:BN45,"<"&C13),CONCATENATE(COUNTIF(Devblogs!BN2:BN45,"<"&C13), " - ",COUNTIF(Devblogs!BN2:BN45,"<="&C13))) -> 6
A14: =Updates!A44 -> 2.7 | B14: =Updates!B44 -> Red Skies | C14: 44337 | D14: =CHOOSE(WEEKDAY(C14,2),"Monday","Tuesday","Wednesday","Thursday","Friday","Saturday","Sunday") -> Friday | E14: =_xludf.DAYS(C14,Devblogs!BK2) -> #NAME? | F14: =IF(COUNTIF(Devblogs!BK2:BK45,"<"&C14)=COUNTIF(Devblogs!BK2:BK45,"<="&C14),COUNTIF(Devblogs!BK2:BK45,"<"&C14),CONCATENATE(COUNTIF(Devblogs!BK2:BK45,"<"&C14), " - ",COUNTIF(Devblogs!BK2:BK45,"<="&C14))) -> 6 - 8
A15: =Updates!A45 -> 2.9 | B15: =Updates!B45 -> Direct Hit | C15: 44435 | D15: =CHOOSE(WEEKDAY(C15,2),"Monday","Tuesday","Wednesday","Thursday","Friday","Saturday","Sunday") -> Friday | E15: =_xludf.DAYS(C15,Devblogs!BH2) -> #NAME? | F15: =IF(COUNTIF(Devblogs!BH2:BH45,"<"&C15)=COUNTIF(Devblogs!BH2:BH45,"<="&C15),COUNTIF(Devblogs!BH2:BH45,"<"&C15),CONCATENATE(COUNTIF(Devblogs!BH2:BH45,"<"&C15), " - ",COUNTIF(Devblogs!BH2:BH45,"<="&C15))) -> 8 - 9
